Workbook

Sheet Ringkasan
A1: AdopTree World — Perhitungan Kapasitas & Anggaran Infrastruktur (Staging + Production)
A2: Pendamping dokumen: kapasitas-sistem-staging-production.md · ringkasan-pengajuan.md — 11 Juli 2026 (rev v1.6: 18 Juli — + ArcGIS · AccuWeather · DeepSeek · AI internal) · Aditira Jamhuri (CTO)
A4: Fase | B4: Periode | C4: Server (Rp/bln) | D4: Software (Rp/bln) | E4: TOTAL (Rp/bln)
A5: Launch (≤ 2.000 akun) | B5: Agu–Des 2026 | C5: =Server!E12 | D5: =Software!C15 | E5: =C5+D5
A6: Growth Y1 (≤ 25 rb akun) | B6: 2027 | C6: =Server!E13 | D6: =Software!D15 | E6: =C6+D6
A7: Scale Y2 (≤ 120 rb akun) | B7: 2028 | C7: =Server!E14 | D7: =Software!E15 | E7: =C7+D7
A9: Anggaran 12 bulan pertama (Agu 2026 – Jul 2027)
A10: Total proyeksi realisasi — base, upgrade per trigger (termasuk buffer 10%); skenario upgrade dini ≈ Rp 82 jt di sheet Anggaran12Bln (v1.6: termasuk ArcGIS + AccuWeather + AI) | C10: =Anggaran12Bln!C10
A11: PLAFON diajukan untuk persetujuan | C11: =Anggaran12Bln!C11
A12: Rasio realisasi base terhadap alokasi infrastruktur PRD §14.4 tahun 2027 (plafon ≈ 45%) | C12: =Anggaran12Bln!C18
A14: Cara pakai: seluruh sel KUNING di sheet Asumsi adalah input — ubah nilainya (kurs, %DAU, harga, volume anchor) dan seluruh workbook menghitung ulang.
A15: Buka di Microsoft Excel / LibreOffice / Google Sheets agar formula terevaluasi. Metodologi & justifikasi lengkap: kapasitas-sistem-staging-production.md.

Sheet Asumsi
A1: Asumsi & Parameter — sel KUNING adalah input; ubah nilainya, seluruh workbook menghitung ulang
A3: Kode | B3: Parameter | C3: Nilai | D3: Satuan | E3: Catatan / Sensitivitas
A4: KURS | B4: Kurs USD → IDR | C4: 16000 | D4: Rp/USD | E4: Fluktuasi ditampung buffer 10%
A5: A1 | B5: DAU sebagai % akun terdaftar | C5: 0.1 | D5: % | E5: ×2 → tetap < 20% utilisasi Tier 1
A6: A2 | B6: Concurrent peak sebagai % DAU | C6: 0.1 | D6: % | E6: jam sibuk malam/akhir pekan
A7: A3 | B7: RPS per user aktif | C7: 0.1 | D7: RPS | E7: ≈ 6 request/menit saat aktif
A8: A4 | B8: Faktor lonjakan trafik | C8: 10 | D8: × | E8: kampanye/PR; 20× dianalisis di dokumen §7.1
A9: A5 | B9: CDN offload halaman publik | C9: 0.7 | D9: % | E9: konservatif; realita biasanya > 85%
A10: A6a | B10: Foto per inspeksi (3 × 1,5 MB) | C10: 4.5 | D10: MB | E10: watermark anti-tamper
A11: A6b | B11: Inspeksi per pohon per tahun | C11: 2 | D11: ×
A12: A12a | B12: Ukuran video | C12: 75 | D12: MB | E12: profil/galeri lahan, posts
A13: A12b | B13: Video per lahan aktif | C13: 1.5 | D13: video
A14: SPH1 | B14: Ukuran photo sphere 360° | C14: 15 | D14: MB
A15: SPH2 | B15: % pohon dengan photo sphere | C15: 0.1 | D15: %
A16: GAL | B16: Media galeri/forum per merchant | C16: 0.15 | D16: GB
A17: CERT | B17: Sertifikat/laporan per adopsi | C17: 0.5 | D17: MB
A18: R2P | B18: Harga R2 per GB per bulan | C18: 0.015 | D18: USD | E18: egress gratis
A19: BUF | B19: Buffer anggaran | C19: 0.1 | D19: % | E19: baris tersendiri di Anggaran12Bln
A20: LHN | B20: Lahan aktif per merchant | C20: 2.5 | D20: lahan
A21: MAP1 | B21: Sesi per DAU per bulan | C21: 30 | D21: sesi
A22: MAP2 | B22: % sesi membuka peta | C22: 0.5 | D22: % | E22: peta = fitur inti AdopTree
A23: MAP3 | B23: Harga Mapbox per 1.000 loads di atas free tier | C23: 5 | D23: USD
A24: MAP4 | B24: Free tier Mapbox | C24: 50000 | D24: loads/bln | E24: web GL loads
A25: MAP5 | B25: Faktor mitigasi peta (thumbnail statis + lazy-load) | C25: 0.4 | D25: × | E25: porsi sesi peta yang benar-benar memuat peta interaktif
A26: EML1 | B26: Email per akun aktif per bulan | C26: 4 | D26: email | E26: rentang dokumen: 2–6
A27: EML2 | B27: Akun aktif = DAU × | C27: 3 | D27: × | E27: proxy MAU
A28: AI1 | B28: Percakapan Tira per DAU per bulan | C28: 3 | D28: percakapan | E28: co-pilot + support 24/7
A29: AI2 | B29: Biaya AI per percakapan (DeepSeek V4 Flash — revisi v1.6; provider lama Rp 150) | C29: 12 | D29: Rp | E29: rentang A11: 50–300; cap harian fail-closed membatasi maksimum
A30: GRW | B30: Cadangan pertumbuhan konten media | C30: 0.5 | D30: % | E30: penebal konservatif atas seluruh media terhitung
A31: BKP | B31: Faktor backup (× ukuran DB, retensi 30 hari) | C31: 2 | D31: × | E31: WAL + basebackup
A33: Anchor volume (PRD §14.2) | C33: Launch 2026 | D33: Growth Y1 2027 | E33: Scale Y2 2028
A34: AKUN | B34: Akun terdaftar | C34: 2000 | D34: 25000 | E34: 120000
A35: POHON | B35: Pohon teradopsi (kumulatif) | C35: 500 | D35: 8000 | E35: 30000
A36: MRCH | B36: Merchant aktif | C36: 30 | D36: 150 | E36: 400
A37: LAHAN | B37: Lahan aktif (= merchant × LHN) | C37: =C36*$C$20 | D37: =D36*$C$20 | E37: =E36*$C$20
A38: APK | B38: Build APK kumulatif (±117 MB/build) | C38: 45 | D38: 90 | E38: 130
A39: DB | B39: Proyeksi ukuran database (GB) | C39: 1 | D39: 15 | E39: 80
A41: Langganan strategis (keputusan founder 18 Jul 2026 — revisi v1.6) | C41: Launch | D41: Y1 | E41: Y2
A42: ARC1 | B42: Harga ArcGIS Online Creator per user per TAHUN (USD; list $700–1.191 — A13) | C42: 1000 | D42: 1000 | E42: 1000
A43: ARC2 | B43: Jumlah seat ArcGIS per fase | C43: 1 | D43: 1 | E43: 2
...

Sheet Beban
A1: Model Beban — formula eksplisit dari anchor PRD §14.2 (dokumen §3)
A3: Metrik | B3: Formula | C3: Launch 2026 | D3: Growth Y1 2027 | E3: Scale Y2 2028
A4: Akun terdaftar | B4: anchor PRD §14.2 (sheet Asumsi) | C4: =Asumsi!C34 | D4: =Asumsi!D34 | E4: =Asumsi!E34
A5: DAU | B5: akun × A1 | C5: =C4*Asumsi!$C$5 | D5: =D4*Asumsi!$C$5 | E5: =E4*Asumsi!$C$5
A6: Concurrent peak | B6: DAU × A2 | C6: =C5*Asumsi!$C$6 | D6: =D5*Asumsi!$C$6 | E6: =E5*Asumsi!$C$6
A7: RPS nominal | B7: concurrent × A3 | C7: =C6*Asumsi!$C$7 | D7: =D6*Asumsi!$C$7 | E7: =E6*Asumsi!$C$7
A8: RPS target sizing | B8: nominal × A4 (lonjakan) | C8: =C7*Asumsi!$C$8 | D8: =D7*Asumsi!$C$8 | E8: =E7*Asumsi!$C$8
A10: Kapasitas komponen (acuan praktik industri — konservatif; dokumen §3.3)
A11: Komponen | B11: Kapasitas aman per unit | C11: Catatan
A12: Rust/Axum BE | B12: ≥ 2.000 RPS/core | C12: praktis bukan bottleneck sampai Y2
A13: Next.js SSR | B13: 50–150 RPS/core | C13: dimitigasi CDN offload (A5)
A14: PostgreSQL + PostGIS | B14: 500–1.000 tx tulis/s | C14: pool koneksi + IOPS NVMe
A15: Redis | B15: 50.000+ ops/s | C15: bukan bottleneck
A16: Meilisearch | B16: ribuan query/s | C16: RAM indeks kecil
A17: ML Tree Service | B17: on-demand, antre | C17: RAM 1–2 GB saat inferensi
A19: Kesimpulan: throughput bukan pendorong biaya — pendorongnya availability + keamanan data (isolasi, backup, enkripsi) + RAM layanan pendukung.

Sheet StorageR2
A1: Storage R2 — SELURUH konten media platform (dokumen §4.1); egress GRATIS berapa pun trafiknya
A3: Item | B3: Formula | C3: Launch 2026 (GB) | D3: Growth Y1 2027 (GB) | E3: Scale Y2 2028 (GB)
A4: Foto inspeksi lapangan (jejak audit ESG) | B4: pohon × A6b × A6a / 1024 | C4: =Asumsi!C35*Asumsi!$C$11*Asumsi!$C$10/1024 | D4: =Asumsi!D35*Asumsi!$C$11*Asumsi!$C$10/1024 | E4: =Asumsi!E35*Asumsi!$C$11*Asumsi!$C$10/1024
A5: Video (profil/galeri lahan, posts, landing) | B5: lahan aktif × A12b × A12a / 1024 | C5: =Asumsi!C37*Asumsi!$C$13*Asumsi!$C$12/1024 | D5: =Asumsi!D37*Asumsi!$C$13*Asumsi!$C$12/1024 | E5: =Asumsi!E37*Asumsi!$C$13*Asumsi!$C$12/1024
A6: Photo sphere 360° | B6: pohon × SPH2 × SPH1 / 1024 | C6: =Asumsi!C35*Asumsi!$C$15*Asumsi!$C$14/1024 | D6: =Asumsi!D35*Asumsi!$C$15*Asumsi!$C$14/1024 | E6: =Asumsi!E35*Asumsi!$C$15*Asumsi!$C$14/1024
A7: Galeri foto lahan, avatar, media forum | B7: merchant × GAL | C7: =Asumsi!C36*Asumsi!$C$16 | D7: =Asumsi!D36*Asumsi!$C$16 | E7: =Asumsi!E36*Asumsi!$C$16
A8: Sertifikat PDF + laporan ESG | B8: pohon × CERT / 1024 | C8: =Asumsi!C35*Asumsi!$C$17/1024 | D8: =Asumsi!D35*Asumsi!$C$17/1024 | E8: =Asumsi!E35*Asumsi!$C$17/1024
A9: APK releases (retensi seluruh build) | B9: build × 117 MB / 1024 | C9: =Asumsi!C38*117/1024 | D9: =Asumsi!D38*117/1024 | E9: =Asumsi!E38*117/1024
A10: Backup DB (retensi 30 hari) | B10: ukuran DB × BKP | C10: =Asumsi!C39*Asumsi!$C$31 | D10: =Asumsi!D39*Asumsi!$C$31 | E10: =Asumsi!E39*Asumsi!$C$31
A11: Subtotal terhitung | B11: jumlah baris di atas | C11: =SUM(C4:C10) | D11: =SUM(D4:D10) | E11: =SUM(E4:E10)
A12: Cadangan pertumbuhan konten (GRW) | B12: subtotal × GRW | C12: =C11*Asumsi!$C$30 | D12: =D11*Asumsi!$C$30 | E12: =E11*Asumsi!$C$30
A13: TOTAL storage (GB) | B13: subtotal + cadangan | C13: =C11+C12 | D13: =D11+D12 | E13: =E11+E12
A14: Biaya per bulan (USD) | B14: total GB × R2P | C14: =C13*Asumsi!$C$18 | D14: =D13*Asumsi!$C$18 | E14: =E13*Asumsi!$C$18
A15: Biaya per bulan (Rp) | B15: USD × KURS | C15: =C14*Asumsi!$C$4 | D15: =D14*Asumsi!$C$4 | E15: =E14*Asumsi!$C$4
A17: Skenario media 5× proyeksi (Rp/bln) | B17: biaya Rp × 5 | C17: =C15*5 | D17: =D15*5 | E17: =E15*5
A18: Catatan: bahkan skenario 5× di Y2 tetap < 15% anggaran bulanan fase tersebut — egress tetap Rp 0. Jalur adaptive streaming (Cloudflare Stream) via revisi anggaran.

Sheet Software
A1: Inventaris Langganan Software — LENGKAP, termasuk yang Rp 0 (dokumen §8.1); titik tengah realistis per bulan
A3: Layanan | B3: Basis perhitungan | C3: Launch 2026 (Rp/bln) | D3: Growth Y1 2027 (Rp/bln) | E3: Scale Y2 2028 (Rp/bln) | F3: Catatan
A4: Cloudflare (plan) | B4: Free → Pro $20/bln mulai Y1 | C4: 0 | D4: =20*Asumsi!$C$4 | E4: =20*Asumsi!$C$4 | F4: Y2 bisa naik Business bila perlu
A5: Cloudflare R2 | B5: sheet StorageR2 (seluruh konten media) | C5: =StorageR2!C15 | D5: =StorageR2!D15 | E5: =StorageR2!E15 | F5: egress gratis
A6: Mapbox | B6: MAX(0; loads efektif − free tier) / 1000 × MAP3 × KURS | C6: =MAX(0,C18-Asumsi!$C$24)/1000*Asumsi!$C$23*Asumsi!$C$4 | D6: =MAX(0,D18-Asumsi!$C$24)/1000*Asumsi!$C$23*Asumsi!$C$4 | E6: =MAX(0,E18-Asumsi!$C$24)/1000*Asumsi!$C$23*Asumsi!$C$4 | F6: loads efektif di baris 18 (sudah termasuk mitigasi MAP5)
A7: Tira AI komersial — DeepSeek API (multi-provider, switch runtime) | B7: DAU × AI1 × AI2 | C7: =Beban!C5*Asumsi!$C$28*Asumsi!$C$29 | D7: =Beban!D5*Asumsi!$C$28*Asumsi!$C$29 | E7: =Beban!E5*Asumsi!$C$28*Asumsi!$C$29 | F7: cap harian fail-closed built-in membatasi maksimum
A8: Email transaksional (Resend → SES) | B8: tier dari volume email di baris 19 | C8: =IF(C19<=3000,0,IF(C19<=50000,20*Asumsi!$C$4,IF(C19<=100000,90*Asumsi!$C$4,C19/1000*0.1*Asumsi!$C$4))) | D8: =IF(D19<=3000,0,IF(D19<=50000,20*Asumsi!$C$4,IF(D19<=100000,90*Asumsi!$C$4,D19/1000*0.1*Asumsi!$C$4))) | E8: =IF(E19<=3000,0,IF(E19<=50000,20*Asumsi!$C$4,IF(E19<=100000,90*Asumsi!$C$4,E19/1000*0.1*Asumsi!$C$4))) | F8: Free 3rb → Pro $20 → Scale $90 → SES $0,10/1.000
A9: Sentry (error monitoring) | B9: Free → Team ~$26 mulai Y1 | C9: 0 | D9: =26*Asumsi!$C$4 | E9: =26*Asumsi!$C$4 | F9: Business ~$80 bila dibutuhkan
A10: Uptime monitor (+ APM di Y2) | B10: Free → ~$25 | C10: 0 | D10: 0 | E10: =25*Asumsi!$C$4
A11: Domain adoptreeworld.com | B11: ~Rp 300 rb/tahun ÷ 12 | C11: =300000/12 | D11: =300000/12 | E11: =300000/12
A12: Container registry | B12: GHCR gratis | C12: 0 | D12: 0 | E12: 0 | F12: Docker Hub Pro ~$11 bila diperlukan
A13: FCM + Web Push (VAPID) | B13: gratis / standar terbuka | C13: 0 | D13: 0 | E13: 0 | F13: push mobile + browser
A14: Jenkins · GitHub · Google OAuth · Instagram Graph API · Sentinel-2 · Meilisearch · Redis · PostgreSQL+PostGIS · ML service · OSS | B14: self-host / free plan | C14: 0 | D14: 0 | E14: 0 | F14: tercantum agar terlihat tidak ada yang terlewat
A15: SUBTOTAL SOFTWARE | B15: jumlah baris 4–14 + langganan strategis (baris 22–24) | C15: =SUM(C4:C14)+SUM(C22:C24) | D15: =SUM(D4:D14)+SUM(D22:D24) | E15: =SUM(E4:E14)+SUM(E22:E24) | F15: v1.6: termasuk ArcGIS + AccuWeather + AI internal; Tira = DeepSeek
A17: Metrik volume (dasar formula di atas) | C17: Launch | D17: Y1 | E17: Y2
A18: Mapbox loads efektif / bln | B18: DAU × MAP1 × MAP2 × MAP5 | C18: =Beban!C5*Asumsi!$C$21*Asumsi!$C$22*Asumsi!$C$25 | D18: =Beban!D5*Asumsi!$C$21*Asumsi!$C$22*Asumsi!$C$25 | E18: =Beban!E5*Asumsi!$C$21*Asumsi!$C$22*Asumsi!$C$25 | F18: free tier 50 rb loads (MAP4)
A19: Volume email / bln | B19: DAU × EML2 × EML1 | C19: =Beban!C5*Asumsi!$C$27*Asumsi!$C$26 | D19: =Beban!D5*Asumsi!$C$27*Asumsi!$C$26 | E19: =Beban!E5*Asumsi!$C$27*Asumsi!$C$26
A21: Langganan strategis (keputusan founder 18 Jul 2026 — v1.6; masuk SUBTOTAL baris 15)
A22: ArcGIS Online (Esri) — analisis GIS profesional & peta MRV | B22: ARC1 × seat ÷ 12 × KURS (dibayar tahunan di muka) | C22: =Asumsi!$C$42*Asumsi!C43*Asumsi!$C$4/12 | D22: =Asumsi!$D$42*Asumsi!D43*Asumsi!$C$4/12 | E22: =Asumsi!$E$42*Asumsi!E43*Asumsi!$C$4/12 | F22: Creator $700–1.191/user/th; minta penawaran Esri Indonesia saat pengadaan (A13)
A23: AccuWeather API — cuaca per lahan | B23: ACW × KURS (cache server-side per lahan/jam menekan volume) | C23: =Asumsi!C44*Asumsi!$C$4 | D23: =Asumsi!D44*Asumsi!$C$4 | E23: =Asumsi!E44*Asumsi!$C$4 | F23: Trial gratis → Standard $25 (225 rb calls) → Elite $500
A24: AI internal engineering — Claude Code / ChatGPT | B24: AIENG × KURS | C24: =Asumsi!C45*Asumsi!$C$4 | D24: =Asumsi!D45*Asumsi!$C$4 | E24: =Asumsi!E45*Asumsi!$C$4 | F24: khusus internal engineering (komersial = DeepSeek, baris 7)

Sheet Server
A1: Spesifikasi & Harga Server per Tier (dokumen §5) — rentang = harga pasar 4 provider (sheet Pembanding)
A3: Komponen | B3: Spesifikasi | C3: Min (Rp/bln) | D3: Max (Rp/bln) | E3: Titik tengah (Rp/bln)
A4: VPS Staging (semua fase) | B4: 2 vCPU / 4 GB / 80 GB NVMe — stack lengkap + Jenkins CI/CD | C4: 150000 | D4: 350000 | E4: =AVERAGE(C4:D4)
A5: Production Tier 1 — Launch | B5: 4 vCPU / 8 GB / 160 GB NVMe, DC Indonesia (UU PDP) | C5: 400000 | D5: 800000 | E5: =AVERAGE(C5:D5)
A6: Production Tier 2 — Growth Y1 | B6: App node 8 vCPU/16 GB + DB node terpisah 4 vCPU/8 GB NVMe | C6: 1300000 | D6: 2600000 | E6: =AVERAGE(C6:D6)
A7: Production Tier 3 — Scale Y2 | B7: 2× app + LB + managed Postgres HA + replica + node ML | C7: 5000000 | D7: 10000000 | E7: =AVERAGE(C7:D7)
A8: VPS Staging — upgrade Y2 (opsional) | B8: 4 vCPU / 8 GB bila antrean build memicu trigger | C8: 250000 | D8: 500000 | E8: =AVERAGE(C8:D8)
A10: Total server per fase (titik tengah)
A11: Fase | B11: Komposisi | E11: Rp/bln
A12: Launch 2026 | B12: Staging + Production Tier 1 | E12: =E4+E5
A13: Growth Y1 2027 | B13: Staging + Production Tier 2 | E13: =E4+E6
A14: Scale Y2 2028 | B14: Staging (upgrade) + Production Tier 3 | E14: =E8+E7
A16: Pemisahan peran (dokumen §5.0b): Builder/CI di staging sejak hari pertama; DB pisah node di Tier 2; HA + replica di Tier 3; backup = R2 off-site (bukan VM).

Sheet Anggaran12Bln
A1: Anggaran 12 Bulan Pertama — Agustus 2026 s.d. Juli 2027 (dokumen §8.3)
A3: Pos | B3: Perhitungan | C3: Jumlah (Rp)
A4: Staging dedicated, 12 bulan | B4: 12 × titik tengah staging | C4: =12*Server!E4
A5: Production Launch + software, 5 bulan (Agu–Des 2026) | B5: 5 × (Prod Tier 1 + subtotal software Launch) | C5: =5*(Server!E5+Software!C15)
A6: Production Growth Y1 + software, 7 bulan (Jan–Jul 2027) | B6: 7 × (Prod Tier 2 + subtotal software Y1) | C6: =7*(Server!E6+Software!D15)
A7: One-time: hardening, uji restore, k6 gate go-live | B7: jam kerja internal, tanpa lisensi | C7: 0
A8: Subtotal | B8: jumlah pos di atas | C8: =SUM(C4:C7)
A9: Buffer (BUF) | B9: subtotal × buffer (Asumsi BUF) | C9: =C8*Asumsi!$C$19
A10: TOTAL PROYEKSI 12 BULAN | B10: subtotal + buffer | C10: =C8+C9
A11: PLAFON DIAJUKAN | B11: menampung base maupun skenario upgrade dini (baris 22–25) | C11: 85000000
A12: Ruang tersisa terhadap plafon | B12: plafon − total proyeksi | C12: =C11-C10
A14: Uji kewajaran terhadap alokasi PRD §14.4
A15: Alokasi infrastruktur PRD 2026 | B15: $3.600 × KURS | C15: =3600*Asumsi!$C$4
A16: Alokasi infrastruktur PRD 2027 | B16: $12.000 × KURS | C16: =12000*Asumsi!$C$4
A17: Rasio total proyeksi vs alokasi 2026 | B17: total ÷ alokasi 2026 | C17: =C10/C15
A18: Rasio total proyeksi vs alokasi 2027 | B18: total ÷ alokasi 2027 | C18: =C10/C16
A20: Mekanisme pengendalian: bila realisasi mendekati plafon, pengeluaran berikutnya kembali dimintakan persetujuan — anggaran tidak dapat terlampaui tanpa sepengetahuan stakeholder.
A22: Skenario upgrade dini — trigger Tier 2 terpicu Nov 2026 (lonjakan pasca-public-launch)
A23: Subtotal skenario dini | B23: 12 × staging + 3 × (Tier 1 + software Launch) + 9 × (Tier 2 + software Y1) | C23: =12*Server!E4+3*(Server!E5+Software!C15)+9*(Server!E6+Software!D15)
A24: Buffer (BUF) | B24: subtotal skenario × buffer | C24: =C23*Asumsi!$C$19
A25: TOTAL skenario upgrade dini | B25: subtotal + buffer | C25: =C23+C24
A26: Ruang tersisa plafon terhadap skenario dini | B26: plafon − total skenario dini | C26: =C11-C25

Sheet Pembanding
A1: Pembanding Harga Pasar — harga publik per Juli 2026 (dokumen §5.5) — ⚠️ WAJIB verifikasi ulang saat pengadaan
A3: Provider | B3: Staging 2 vCPU/4 GB | C3: Production 4 vCPU/8 GB | D3: Catatan
A4: IDCloudHost (Indonesia) | B4: ≈ Rp 175–300 rb | C4: ≈ Rp 400–600 rb | D4: Pay-as-you-go; ekstrapolasi dari harga publik 2 vCPU/2 GB Rp 87–149 rb; DC Indonesia ✓
A5: Biznet Gio NEO Lite (Indonesia) | B5: ≈ Rp 200–300 rb | C5: ≈ Rp 400–600 rb | D5: NVMe, free bandwidth; DC Indonesia ✓
A6: DigitalOcean (Singapura) | B6: $24–32 (Rp 390–520 rb) | C6: $48–63 (Rp 780 rb–1 jt) | D6: Tooling bagus; data PII keluar RI → hanya cadangan
A7: Vultr (Singapura) | B7: $20–24 (Rp 330–390 rb) | C7: $40–48 (Rp 650–780 rb) | D7: idem
A9: Kesimpulan: rentang proposal (staging Rp 150–350 rb; production Rp 400–800 rb) = harga pasar apa adanya, tanpa margin. Preferensi provider Indonesia (UU PDP data residency untuk NIK/KTP + latency domestik).
A11: Sumber harga software (dokumen Appendix B)
A12: Cloudflare R2 $0,015/GB/bln egress $0; Cloudflare Pro $20/bln
A13: Mapbox: free 50 rb web loads + 50 rb static + 25 rb mobile MAU + 100 rb geocoding/bln; ~$5/1.000 loads setelahnya
A14: Resend: Free 3 rb → Pro $20 (50 rb) → Scale $90 (100 rb); AWS SES $0,10/1.000 email
A15: Sentry: Developer free → Team ~$26 → Business ~$80/bln
A16: OpenAI / Google Gemini: harga per token publik; multi-provider → model termurah yang memadai

Sheet OnPremise
A1: Transisi On-Premise Tahun ke-3 — kalkulasi lengkap di awal (dokumen §10); sel KUNING = input
A3: CapEx Hardware (skala Tier 3) | B3: Basis | C3: Nilai (Rp) | D3: Catatan
A4: 2× server aplikasi + DB (HA) | B4: EPYC/Xeon 16–32 core, 128 GB, NVMe RAID | C4: 150000000 | D4: rentang 120–180 jt
A5: 1× server utilitas (ML, monitoring) | B5: 8–16 core, 64 GB | C5: 40000000 | D5: rentang 30–50 jt
A6: Jaringan (switch, firewall, IPMI) | C6: 20000000 | D6: rentang 15–30 jt
A7: Suku cadang (disk, PSU, RAM) | B7: wajib utk RTO tanpa vendor | C7: 20000000 | D7: rentang 15–25 jt
A8: TOTAL CapEx | B8: jumlah baris di atas | C8: =SUM(C4:C7) | D8: rentang 180–285 jt
A9: Umur amortisasi (tahun) | B9: input | C9: 4
A10: Amortisasi per bulan | B10: CapEx / (umur × 12) | C10: =C8/(C9*12)
A12: OpEx Bulanan On-Premise | B12: Basis | C12: Nilai (Rp/bln) | D12: Catatan
A13: Colocation ~4U DC Indonesia ISO 27001 | B13: listrik redundan + pendingin + bandwidth | C13: 4500000 | D13: rentang 3–6 jt
A14: SDM ops / on-call 24/7 (±0,5 FTE) | B14: pekerjaan yg di cloud dikerjakan vendor | C14: 6500000 | D14: rentang 5–8 jt
A15: Backup off-site (tetap R2) + monitoring | B15: §4.1 — backup tidak satu lokasi dgn server | C15: 500000
A16: TOTAL OpEx / bulan | B16: jumlah baris di atas | C16: =SUM(C13:C15) | D16: rentang 8,5–14,5 jt
A18: Perbandingan TCO tahun ke-3 (per bulan)
A19: On-premise efektif (OpEx + amortisasi) | B19: OpEx + amortisasi CapEx | C19: =C16+C10 | D19: di titik masuk th-3 SETARA dgn cloud; menang saat cloud tumbuh > ambang
A20: Cloud Tier 3 (dari sheet Ringkasan) | B20: server + software Scale Y2 | C20: =Ringkasan!E7
A21: Selisih (cloud − on-premise) | B21: positif = on-premise lebih hemat | C21: =C20-C19
A22: Payback CapEx pada ambang eksekusi (bulan) | B22: CapEx ÷ (ambang eksekusi − TCO on-premise) | C22: =IF(C23-C19>0,C8/(C23-C19),"—")
A23: Ambang praktis eksekusi (belanja cloud sustained/bln) | B23: belanja cloud sustained per bulan | C23: 25000000 | D23: kriteria §10.4 (Rp 20–25 jt) — input; payback ≈2,2 th pada ambang ini
A25: Plot Dana 3 Tahun (proposal pendanaan)
A26: Periode | B26: Skema | C26: Anggaran (Rp) | D26: Catatan
A27: Tahun 1 (Agu 2026–Jul 2027) | B27: Cloud — plafon proposal ini | C27: =Anggaran12Bln!C11 | D27: realisasi ≈ Rp 40 jt
A28: Tahun 2 (Agu 2027–Jul 2028) | B28: Cloud Growth→Scale: 5 bln Y1 + 7 bln Y2 + buffer | C28: =(5*Ringkasan!E6+7*Ringkasan!E7)*(1+Asumsi!$C$19) | D28: mengikuti trigger
A29: Tahun 3 (Agu 2028–Jul 2029) | B29: Cloud ±8 bln + CapEx on-prem + parallel run 4 bln | C29: =(8*Ringkasan!E7+C8+4*C16)*(1+Asumsi!$C$19) | D29: cutover bertahap
A30: TOTAL 3 TAHUN | B30: jumlah | C30: =SUM(C27:C29)
A31: Tahun 4+ (steady on-premise) | B31: OpEx + amortisasi × 12 | C31: =(C16+C10)*12 | D31: vs tetap cloud > Rp 240–300 jt/th → hemat mulai th-4
A32: Alokasi infra PRD §14.4 tiga tahun | B32: ($3.600+$12.000+$36.000) × KURS | C32: =(3600+12000+36000)*Asumsi!$C$4
A33: Rasio plot vs alokasi PRD | B33: total 3 th ÷ alokasi | C33: =C30/C32

Sheet SDM
A1: SDM / MANPOWER — model biaya (pasangan: anggaran-sdm-manpower.md, v1.0 · 17 Jul 2026)
A2: Sel KUNING = asumsi, boleh diganti — seluruh angka menghitung ulang. Semua nilai dalam Rp juta. Loaded = gaji × faktor beban.
A4: ASUMSI
A5: Faktor beban pemberi kerja (BPJS 10,24% + THR 8,33% + cadangan) | B5: 1.2
A6: Stipend founder/bln — fase Launch & Growth (Rp jt) | B6: 10
A7: Stipend founder/bln — fase Scale 2028 (Rp jt) | B7: 20
A8: Jumlah founder | B8: 3
A9: Kurs USD (uji kewajaran vs PRD §14.4) | B9: 16000
A11: ROSTER (jumlah orang per fase; gaji = asumsi pasar 2026 mid-level remote-first)
A12: Kode | B12: Peran | C12: Gaji/bln | D12: Jml Launch | E12: Jml 2027 | F12: Jml 2028 | G12: Loaded satuan | H12: Biaya/bln Launch | I12: Biaya/bln 2027 | J12: Biaya/bln 2028
A13: L1 | B13: Fullstack Engineer (mid) | C13: 14 | D13: 1 | E13: 1 | F13: 1 | G13: =C13*$B$5 | H13: =G13*D13 | I13: =G13*E13 | J13: =G13*F13
A14: L2 | B14: Ops & Support Admin | C14: 7 | D14: 1 | E14: 1 | F14: 1 | G14: =C14*$B$5 | H14: =G14*D14 | I14: =G14*E14 | J14: =G14*F14
A15: L3 | B15: Koordinator Operasi Lapangan | C15: 8 | D15: 1 | E15: 2 | F15: 4 | G15: =C15*$B$5 | H15: =G15*D15 | I15: =G15*E15 | J15: =G15*F15
A16: L4 | B16: BD / Merchant Onboarding | C16: 9 | D16: 1 | E16: 2 | F16: 2 | G16: =C16*$B$5 | H16: =G16*D16 | I16: =G16*E16 | J16: =G16*F16
A17: G1 | B17: DevOps/SRE Engineer (persiapan on-premise §7) | C17: 15 | D17: 0 | E17: 1 | F17: 1 | G17: =C17*$B$5 | H17: =G17*D17 | I17: =G17*E17 | J17: =G17*F17
A18: G2 | B18: Mobile Engineer (Flutter) | C18: 14 | D18: 0 | E18: 1 | F18: 1 | G18: =C18*$B$5 | H18: =G18*D18 | I18: =G18*E18 | J18: =G18*F18
A19: G3 | B19: Customer Support | C19: 6.5 | D19: 0 | E19: 1 | F19: 2 | G19: =C19*$B$5 | H19: =G19*D19 | I19: =G19*E19 | J19: =G19*F19
A20: G5 | B20: Finance & Admin | C20: 8 | D20: 0 | E20: 1 | F20: 2 | G20: =C20*$B$5 | H20: =G20*D20 | I20: =G20*E20 | J20: =G20*F20
A21: G7 | B21: Content & Community | C21: 7 | D21: 0 | E21: 1 | F21: 1 | G21: =C21*$B$5 | H21: =G21*D21 | I21: =G21*E21 | J21: =G21*F21
A22: S1 | B22: Infra/Platform Engineer #2 (rotasi on-call on-premise) | C22: 15 | D22: 0 | E22: 0 | F22: 1 | G22: =C22*$B$5 | H22: =G22*D22 | I22: =G22*E22 | J22: =G22*F22
A23: S2 | B23: Backend Engineer | C23: 16 | D23: 0 | E23: 0 | F23: 1 | G23: =C23*$B$5 | H23: =G23*D23 | I23: =G23*E23 | J23: =G23*F23
A24: S3 | B24: QA Engineer | C24: 10 | D24: 0 | E24: 0 | F24: 1 | G24: =C24*$B$5 | H24: =G24*D24 | I24: =G24*E24 | J24: =G24*F24
... A26: S7 | B26: Data/ML Engineer (opsional — trigger registri karbon) | C26: 16 | D26: 0 | E26: 0 | F26: 1 | G26: =C26*$B$5 | H26: =G26*D26 | I26: =G26*E26 | J26: =G26*F26
A27: FND | B27: Stipend 3 founder (Launch/Growth vs Scale) | D27: 3 | E27: 3 | F27: 3 | H27: =$B$8*$B$6*$B$5 | I27: =$B$8*$B$6*$B$5 | J27: =$B$8*$B$7*$B$5
A29: TOTAL
A30: Headcount total (termasuk founder) | D30: =SUM(D13:D26)+$B$8 | E30: =SUM(E13:E26)+$B$8 | F30: =SUM(F13:F26)+$B$8
A31: Biaya SDM/bln (Rp jt, loaded) | H31: =SUM(H13:H27) | I31: =SUM(I13:I27) | J31: =SUM(J13:J27)
A33: REKAP TAHUNAN & UJI KEWAJARAN (Rp jt)
A34: 2026 (Agu–Des, 5 bln roster Launch) | B34: =5*H31 | D34: Alokasi Team PRD 2026 ($36.000) | E34: =36000*$B$9/1000000 | F34: % terpakai | G34: =B34/E34
A35: 2027 (bertahap: 3 bln awal + 3 bln tengah + 6 bln penuh — lihat §4 dokumen) | B35: =3*(H31+G17+G18)+3*(H31+G17+G18+G19+G15+G20)+6*I31 | D35: Alokasi Team PRD 2027 ($120.000) | E35: =120000*$B$9/1000000 | F35: % terpakai | G35: =B35/E35
A36: 2028 (12 bln roster Scale — S7 opsional termasuk) | B36: =12*J31 | D36: Alokasi Team PRD 2028 ($360.000) | E36: =360000*$B$9/1000000 | F36: % terpakai | G36: =B36/E36
A37: Total 3 tahun (kalender) | B37: =B34+B35+B36 | D37: Total alokasi 3 th | E37: =E34+E35+E36 | F37: % terpakai | G37: =B37/E37
A39: PLAFON 12 BULAN PERTAMA (Agu 2026 – Jul 2027)
A40: Realisasi proyeksi (5 bln Launch + 7 bln 2027 bertahap) | B40: =5*H31+3*(H31+G17+G18)+3*(H31+G17+G18+G19+G15+G20)+1*I31
A41: Plafon diajukan (buffer ≈10%) | B41: 1500 | D41: → realisasi/plafon | E41: =B40/B41
A43: CATATAN ON-PREMISE (selaras §10.2 dok. infrastruktur & §7 dok. SDM)
A44: Pos "SDM on-call ±0,5 FTE Rp 5–8 jt/bln" pada OpEx on-premise = porsi 0,5 FTE dari G1+S1 di sheet ini — hitung SEKALI saat konsolidasi (tidak ada pos ganda).
A45: Cek: 0,5 × loaded G1 | B45: =0.5*G17 | C45: berada dalam rentang 5–8 jt? (§10.2)
